d0d5ccef4 Hitachi: add support for Hitachi VSP One B20
2025/10/09 14:53:08
all develop-inst-nodeps: /opt/stack/tempest
all installed: attrs==25.3.0,autopage==0.5.2,bcrypt==4.0.1,certifi==2025.10.5,cffi==1.17.1,charset-normalizer==3.4.2,cliff==4.11.0,cmd2==2.7.0,cryptography==43.0.3,debtcollector==3.0.0,defusedxml==0.7.1,fasteners==0.19,fixtures==4.2.5,idna==3.10,iso8601==2.1.0,jsonschema==4.25.0,jsonschema-specifications==2025.4.1,markdown-it-py==3.0.0,mdurl==0.1.2,msgpack==1.1.1,netaddr==1.3.0,oslo.concurrency==7.2.0,oslo.config==10.0.0,oslo.context==6.1.0,oslo.i18n==6.6.0,oslo.log==7.2.1,oslo.serialization==5.8.0,oslo.utils==9.1.0,packaging==25.0,paramiko==3.5.1,pbr==7.0.1,prettytable==3.16.0,psutil==7.0.0,pycparser==2.22,Pygments==2.19.2,PyNaCl==1.5.0,pyparsing==3.2.3,pyperclip==1.9.0,python-dateutil==2.9.0.post0,python-subunit==1.4.4,PyYAML==6.0.2,referencing==0.36.2,requests==2.32.4,rfc3986==2.0.0,rich==14.1.0,rich-argparse==1.7.1,rpds-py==0.26.0,six==1.17.0,stestr==4.2.0,stevedore==5.5.0,-e git+https://opendev.org/openstack/tempest.git@93df2d2d3e73788db982be0f4b85e3451343c94c#egg=tempest,testscenarios==0.5.0,testtools==2.7.2,tomlkit==0.13.3,typing_extensions==4.14.1,tzdata==2025.2,urllib3==1.26.20,voluptuous==0.15.2,wcwidth==0.2.13,wrapt==1.17.2
all run-test-pre: PYTHONHASHSEED='4141591640'
all run-test: commands[0] | find . -type f -name '*.pyc' -delete
all run-test: commands[1] | tempest run --regex tempest.api.volume.test_volumes_negative.VolumesNegativeTest.test_volume_extend_with_size_smaller_than_original_size
{0} setUpClass (tempest.api.volume.test_volumes_negative.VolumesNegativeTest) [0.000000s] ... FAILED

Captured traceback:
~~~~~~~~~~~~~~~~~~~
    Traceback (most recent call last):

      File "/opt/stack/tempest/tempest/test.py", line 185, in setUpClass
    raise value.with_traceback(trace)

      File "/opt/stack/tempest/tempest/test.py", line 170, in setUpClass
    cls.setup_credentials()

      File "/opt/stack/tempest/tempest/api/volume/base.py", line 62, in setup_credentials
    super(BaseVolumeTest, cls).setup_credentials()

      File "/opt/stack/tempest/tempest/test.py", line 398, in setup_credentials
    manager = cls.get_client_manager(

      File "/opt/stack/tempest/tempest/test.py", line 727, in get_client_manager
    cred_provider = cls._get_credentials_provider()

      File "/opt/stack/tempest/tempest/test.py", line 702, in _get_credentials_provider
    cls._creds_provider = credentials.get_credentials_provider(

      File "/opt/stack/tempest/tempest/common/credentials_factory.py", line 141, in get_credentials_provider
    **get_dynamic_provider_params(identity_version))

      File "/opt/stack/tempest/tempest/common/credentials_factory.py", line 72, in get_dynamic_provider_params
    admin_creds = admin_creds or get_configured_admin_credentials(

      File "/opt/stack/tempest/tempest/common/credentials_factory.py", line 257, in get_configured_admin_credentials
    credentials = get_credentials(fill_in=fill_in,

      File "/opt/stack/tempest/tempest/common/credentials_factory.py", line 300, in get_credentials
    return auth.get_credentials(auth_url,

      File "/opt/stack/tempest/tempest/lib/auth.py", line 648, in get_credentials
    auth_provider = auth_provider_class(

      File "/opt/stack/tempest/tempest/lib/auth.py", line 264, in __init__
    super(KeystoneAuthProvider, self).__init__(credentials, scope)

      File "/opt/stack/tempest/tempest/lib/auth.py", line 92, in __init__
    raise exceptions.InvalidCredentials(message)

    tempest.lib.exceptions.InvalidCredentials: Invalid Credentials
Details: Credentials are: {'domain_id': None, 'domain_name': 'Default', 'username': None, 'project_domain_id': None, 'project_domain_name': 'Default', 'project_id': None, 'project_name': None, 'tenant_id': None, 'tenant_name': None, 'user_domain_id': None, 'user_domain_name': 'Default', 'user_id': None, 'system': None} Password is not defined.


No tests were successful during the run

==============================
Failed 1 tests - output below:
==============================

setUpClass (tempest.api.volume.test_volumes_negative.VolumesNegativeTest)
-------------------------------------------------------------------------

Captured traceback:
~~~~~~~~~~~~~~~~~~~
    Traceback (most recent call last):

      File "/opt/stack/tempest/tempest/test.py", line 185, in setUpClass
    raise value.with_traceback(trace)

      File "/opt/stack/tempest/tempest/test.py", line 170, in setUpClass
    cls.setup_credentials()

      File "/opt/stack/tempest/tempest/api/volume/base.py", line 62, in setup_credentials
    super(BaseVolumeTest, cls).setup_credentials()

      File "/opt/stack/tempest/tempest/test.py", line 398, in setup_credentials
    manager = cls.get_client_manager(

      File "/opt/stack/tempest/tempest/test.py", line 727, in get_client_manager
    cred_provider = cls._get_credentials_provider()

      File "/opt/stack/tempest/tempest/test.py", line 702, in _get_credentials_provider
    cls._creds_provider = credentials.get_credentials_provider(

      File "/opt/stack/tempest/tempest/common/credentials_factory.py", line 141, in get_credentials_provider
    **get_dynamic_provider_params(identity_version))

      File "/opt/stack/tempest/tempest/common/credentials_factory.py", line 72, in get_dynamic_provider_params
    admin_creds = admin_creds or get_configured_admin_credentials(

      File "/opt/stack/tempest/tempest/common/credentials_factory.py", line 257, in get_configured_admin_credentials
    credentials = get_credentials(fill_in=fill_in,

      File "/opt/stack/tempest/tempest/common/credentials_factory.py", line 300, in get_credentials
    return auth.get_credentials(auth_url,

      File "/opt/stack/tempest/tempest/lib/auth.py", line 648, in get_credentials
    auth_provider = auth_provider_class(

      File "/opt/stack/tempest/tempest/lib/auth.py", line 264, in __init__
    super(KeystoneAuthProvider, self).__init__(credentials, scope)

      File "/opt/stack/tempest/tempest/lib/auth.py", line 92, in __init__
    raise exceptions.InvalidCredentials(message)

    tempest.lib.exceptions.InvalidCredentials: Invalid Credentials
Details: Credentials are: {'domain_id': None, 'domain_name': 'Default', 'username': None, 'project_domain_id': None, 'project_domain_name': 'Default', 'project_id': None, 'project_name': None, 'tenant_id': None, 'tenant_name': None, 'user_domain_id': None, 'user_domain_name': 'Default', 'user_id': None, 'system': None} Password is not defined.



======
Totals
======
Ran: 1 tests in 0.0000 sec.
 - Passed: 0
 - Skipped: 0
 - Expected Fail: 0
 - Unexpected Success: 0
 - Failed: 1
Sum of execute time for each test: 0.0000 sec.

==============
Worker Balance
==============
 - Worker 0 (1 tests) => 0:00:00
ERROR: InvocationError for command /opt/stack/tempest/.tox/tempest/bin/tempest run --regex tempest.api.volume.test_volumes_negative.VolumesNegativeTest.test_volume_extend_with_size_smaller_than_original_size (exited with code 1)
___________________________________ summary ____________________________________
ERROR:   all: commands failed
